<?xml version='1.0' encoding='UTF-8'?>
<sdf version="1.6">
  <model name="bluerov2">
    <pose>0 0 0 0 0 0</pose>

    <!-- BlueROV2 thruster reference: http://www.ardusub.com/introduction/features.html -->

    <link name="base_link">
      <inertial>
        <pose>0.0 0.0 0.011 0 0 0</pose>
        <mass>10.0</mass>
        <inertia>
          <ixx>0.099</ixx>
          <ixy>0</ixy>
          <ixz>0</ixz>
          <iyy>0.178</iyy>
          <iyz>0</iyz>
          <izz>0.269</izz>
        </inertia>
      </inertial>

      <visual name="base_link_visual">
        <geometry>
          <mesh>
            <uri>model://bluerov2/meshes/bluerov2.dae</uri>
            <scale>0.025 0.025 0.025</scale>
          </mesh>
        </geometry>
      </visual>

      <!-- Collision volume * fluid_density == displaced mass, used by BuoyancyPlugin -->
      <collision name="base_link_collision">
        <pose>0.0 0.0 0.06 0 0 0</pose>
        <geometry>
          <box>
            <size>0.457 0.338 0.065</size>
          </box>
        </geometry>
      </collision>

      <!-- IMU sensor for EKF -->
      <sensor name="imu_sensor" type="imu">
        <pose>0 0 0 3.142 0 0</pose>
        <always_on>true</always_on>

        <!-- Reduced from 1000 Hz to 100 Hz.
             100 Hz is enough for robot_localization EKF and much lighter. -->
        <update_rate>100</update_rate>
      </sensor>

      <!-- 2D lidar-like sonar for SLAM Toolbox and Nav2 -->
      <sensor name="navigation_lidar" type="gpu_lidar">
        <pose>0.25 0 0.12 0 0 0</pose>
        <always_on>true</always_on>

        <!-- Disable Gazebo laser visualization.
             RViz2 already displays /scan. -->
        <visualize>false</visualize>

        <!-- Reduced from 10 Hz to 5 Hz for lower bridge/RViz/SLAM load. -->
        <update_rate>5</update_rate>

        <topic>/scan</topic>
        <gz_frame_id>laser_link</gz_frame_id>

        <lidar>
          <scan>
            <horizontal>
              <!-- Reduced from 720 to 360 rays.
                   This is enough for 180-degree mapping and Nav2. -->
              <samples>360</samples>
              <resolution>1</resolution>

              <!-- 180 degree front scan -->
              <min_angle>-1.57079633</min_angle>
              <max_angle>1.57079633</max_angle>
            </horizontal>
          </scan>

          <range>
            <min>0.20</min>
            <max>5.0</max>

            <!-- Reduced precision for better performance. -->
            <resolution>0.05</resolution>
          </range>

          <noise>
            <type>gaussian</type>
            <mean>0.0</mean>
            <stddev>0.01</stddev>
          </noise>
        </lidar>
      </sensor>
    </link>

    <!-- Hydrodynamics plugin -->
    <plugin
        filename="gz-sim-hydrodynamics-system"
        name="gz::sim::systems::Hydrodynamics">
      <link_name>base_link</link_name>
      <water_density>998.0</water_density>

      <!-- Added mass -->
      <xDotU>0</xDotU>
      <yDotV>0</yDotV>
      <zDotW>0</zDotW>
      <kDotP>0</kDotP>
      <mDotQ>0</mDotQ>
      <nDotR>0</nDotR>

      <!-- First order damping -->
      <xU>-8.0</xU>
      <yV>-60.0</yV>
      <zW>-20.0</zW>

      <!-- Strong roll / pitch damping to keep robot level -->
      <kP>-20.0</kP>
      <mQ>-20.0</mQ>

      <!-- Lower yaw damping so robot can rotate in 2D -->
      <nR>-2.0</nR>

      <!-- Second order damping -->
      <xUabsU>-33.732</xUabsU>
      <yVabsV>-100.0</yVabsV>
      <zWabsW>-73.225</zWabsW>

      <!-- Strong roll / pitch damping -->
      <kPabsP>-30.0</kPabsP>
      <mQabsQ>-30.0</mQabsQ>

      <!-- Lower yaw damping -->
      <nRabsR>-2.0</nRabsR>
    </plugin>

    <link name="thruster1">
      <pose>0.14 -0.092 0.0 -1.571 1.571 -0.785</pose>
      <visual name="thruster_prop_visual">
        <pose>0 0 0 -1.571 0 0</pose>
        <geometry>
          <mesh>
            <uri>model://bluerov2/meshes/t200_ccw_prop.dae</uri>
          </mesh>
        </geometry>
      </visual>
      <inertial>
        <mass>0.002</mass>
        <inertia>
          <ixx>0.001</ixx>
          <ixy>0</ixy>
          <ixz>0</ixz>
          <iyy>0.001</iyy>
          <iyz>0</iyz>
          <izz>0.001</izz>
        </inertia>
      </inertial>
    </link>

    <link name="thruster2">
      <pose>0.14 0.092 0.0 -1.571 1.571 -2.356</pose>
      <visual name="thruster_prop_visual">
        <pose>0 0 0 -1.571 0 0</pose>
        <geometry>
          <mesh>
            <uri>model://bluerov2/meshes/t200_ccw_prop.dae</uri>
          </mesh>
        </geometry>
      </visual>
      <inertial>
        <mass>0.002</mass>
        <inertia>
          <ixx>0.001</ixx>
          <ixy>0</ixy>
          <ixz>0</ixz>
          <iyy>0.001</iyy>
          <iyz>0</iyz>
          <izz>0.001</izz>
        </inertia>
      </inertial>
    </link>

    <link name="thruster3">
      <pose>-0.14 -0.092 0.0 -1.571 1.571 0.785</pose>
      <visual name="thruster_prop_visual">
        <pose>0 0 0 1.571 0 0</pose>
        <geometry>
          <mesh>
            <uri>model://bluerov2/meshes/t200_cw_prop.dae</uri>
          </mesh>
        </geometry>
      </visual>
      <inertial>
        <mass>0.002</mass>
        <inertia>
          <ixx>0.001</ixx>
          <ixy>0</ixy>
          <ixz>0</ixz>
          <iyy>0.001</iyy>
          <iyz>0</iyz>
          <izz>0.001</izz>
        </inertia>
      </inertial>
    </link>

    <link name="thruster4">
      <pose>-0.14 0.092 0.0 -1.571 1.571 2.356</pose>
      <visual name="thruster_prop_visual">
        <pose>0 0 0 1.571 0 0</pose>
        <geometry>
          <mesh>
            <uri>model://bluerov2/meshes/t200_cw_prop.dae</uri>
          </mesh>
        </geometry>
      </visual>
      <inertial>
        <mass>0.002</mass>
        <inertia>
          <ixx>0.001</ixx>
          <ixy>0</ixy>
          <ixz>0</ixz>
          <iyy>0.001</iyy>
          <iyz>0</iyz>
          <izz>0.001</izz>
        </inertia>
      </inertial>
    </link>

    <link name="thruster5">
      <pose>0.0 -0.109 0.077 0 0 0</pose>
      <visual name="thruster_prop_visual">
        <pose>0 0 0 -1.571 0 1.571</pose>
        <geometry>
          <mesh>
            <uri>model://bluerov2/meshes/t200_ccw_prop.dae</uri>
          </mesh>
        </geometry>
      </visual>
      <inertial>
        <mass>0.002</mass>
        <inertia>
          <ixx>0.001</ixx>
          <ixy>0</ixy>
          <ixz>0</ixz>
          <iyy>0.001</iyy>
          <iyz>0</iyz>
          <izz>0.001</izz>
        </inertia>
      </inertial>
    </link>

    <link name="thruster6">
      <pose>0.0 0.109 0.077 0 0 0</pose>
      <visual name="thruster_prop_visual">
        <pose>0 0 0 1.571 0 1.571</pose>
        <geometry>
          <mesh>
            <uri>model://bluerov2/meshes/t200_cw_prop.dae</uri>
          </mesh>
        </geometry>
      </visual>
      <inertial>
        <mass>0.002</mass>
        <inertia>
          <ixx>0.001</ixx>
          <ixy>0</ixy>
          <ixz>0</ixz>
          <iyy>0.001</iyy>
          <iyz>0</iyz>
          <izz>0.001</izz>
        </inertia>
      </inertial>
    </link>

    <joint name="thruster1_joint" type="revolute">
      <parent>base_link</parent>
      <child>thruster1</child>
      <axis>
        <xyz>0 0 -1</xyz>
      </axis>
    </joint>

    <joint name="thruster2_joint" type="revolute">
      <parent>base_link</parent>
      <child>thruster2</child>
      <axis>
        <xyz>0 0 -1</xyz>
      </axis>
    </joint>

    <joint name="thruster3_joint" type="revolute">
      <parent>base_link</parent>
      <child>thruster3</child>
      <axis>
        <xyz>0 0 -1</xyz>
      </axis>
    </joint>

    <joint name="thruster4_joint" type="revolute">
      <parent>base_link</parent>
      <child>thruster4</child>
      <axis>
        <xyz>0 0 -1</xyz>
      </axis>
    </joint>

    <joint name="thruster5_joint" type="revolute">
      <parent>base_link</parent>
      <child>thruster5</child>
      <axis>
        <xyz>0 0 -1</xyz>
      </axis>
    </joint>

    <joint name="thruster6_joint" type="revolute">
      <parent>base_link</parent>
      <child>thruster6</child>
      <axis>
        <xyz>0 0 -1</xyz>
      </axis>
    </joint>

    <plugin
        filename="gz-sim-thruster-system"
        name="gz::sim::systems::Thruster">
      <namespace>bluerov2</namespace>
      <joint_name>thruster1_joint</joint_name>
      <thrust_coefficient>0.02</thrust_coefficient>
      <fluid_density>998.0</fluid_density>
      <propeller_diameter>0.1</propeller_diameter>
      <velocity_control>true</velocity_control>
      <use_angvel_cmd>False</use_angvel_cmd>
    </plugin>

    <plugin
        filename="gz-sim-thruster-system"
        name="gz::sim::systems::Thruster">
      <namespace>bluerov2</namespace>
      <joint_name>thruster2_joint</joint_name>
      <thrust_coefficient>0.02</thrust_coefficient>
      <fluid_density>998.0</fluid_density>
      <propeller_diameter>0.1</propeller_diameter>
      <velocity_control>true</velocity_control>
      <use_angvel_cmd>False</use_angvel_cmd>
    </plugin>

    <plugin
        filename="gz-sim-thruster-system"
        name="gz::sim::systems::Thruster">
      <namespace>bluerov2</namespace>
      <joint_name>thruster3_joint</joint_name>
      <thrust_coefficient>-0.02</thrust_coefficient>
      <fluid_density>998.0</fluid_density>
      <propeller_diameter>0.1</propeller_diameter>
      <velocity_control>true</velocity_control>
      <use_angvel_cmd>False</use_angvel_cmd>
    </plugin>

    <plugin
        filename="gz-sim-thruster-system"
        name="gz::sim::systems::Thruster">
      <namespace>bluerov2</namespace>
      <joint_name>thruster4_joint</joint_name>
      <thrust_coefficient>-0.02</thrust_coefficient>
      <fluid_density>998.0</fluid_density>
      <propeller_diameter>0.1</propeller_diameter>
      <velocity_control>true</velocity_control>
      <use_angvel_cmd>False</use_angvel_cmd>
    </plugin>

    <plugin
        filename="gz-sim-thruster-system"
        name="gz::sim::systems::Thruster">
      <namespace>bluerov2</namespace>
      <joint_name>thruster5_joint</joint_name>
      <thrust_coefficient>0.02</thrust_coefficient>
      <fluid_density>998.0</fluid_density>
      <propeller_diameter>0.1</propeller_diameter>
      <velocity_control>true</velocity_control>
      <use_angvel_cmd>False</use_angvel_cmd>
    </plugin>

    <plugin
        filename="gz-sim-thruster-system"
        name="gz::sim::systems::Thruster">
      <namespace>bluerov2</namespace>
      <joint_name>thruster6_joint</joint_name>
      <thrust_coefficient>-0.02</thrust_coefficient>
      <fluid_density>998.0</fluid_density>
      <propeller_diameter>0.1</propeller_diameter>
      <velocity_control>true</velocity_control>
      <use_angvel_cmd>False</use_angvel_cmd>
    </plugin>

    <!--
    ArduPilotPlugin disabled for direct ROS 2 thruster control.

    We are controlling the Gazebo thruster command topics directly from ROS 2:
      /thruster1/cmd_thrust
      /thruster2/cmd_thrust
      /thruster3/cmd_thrust
      /thruster4/cmd_thrust
      /thruster5/cmd_thrust
      /thruster6/cmd_thrust

    If ArduPilotPlugin is enabled at the same time, it can interfere with
    the direct /cmd_thrust commands from ros_gz_bridge and controllers.
    -->

    <!-- Odometry + TF for ROS 2 Nav2 and depth control -->
    <plugin
      filename="libgz-sim-odometry-publisher-system.so"
      name="gz::sim::systems::OdometryPublisher">
      <odom_frame>odom</odom_frame>
      <robot_base_frame>base_link</robot_base_frame>
      <odom_topic>/model/bluerov2/odometry</odom_topic>
      <tf_topic>/model/bluerov2/tf</tf_topic>
      <dimensions>3</dimensions>

      <!-- Reduced from 30 Hz to 20 Hz.
           EKF publishes /odometry/filtered for Nav2. -->
      <odom_publish_frequency>20</odom_publish_frequency>
    </plugin>

  </model>
</sdf>
